Workbook

Sheet Tareas
A1: Tarea | B1: ID de requisito (Link) | C1: Tiempo estimado (horas) | D1: Tiempo real (horas) | E1: Owner | F1: Estado
A2: Crear y configuración de entorno de Conda en la carpeta del proyecto | B2: =+TablaBacklog[[#This Row],[ID]] -> 1 | C2: 0.5 | D2: 0.25 | E2: Victor | F2: Completado
A3: Estudio de la documentación de FastAPI | B3: =+Requisitos!C2 -> 1 | C3: 1 | D3: 0.25 | E3: Juan | F3: Completado
A4: Estudio de la documentación de FastAPI | B4: =+Requisitos!C2 -> 1 | C4: 1 | D4: 0.25 | E4: Pedro | F4: Completado
A5: Estudio de la documentación de FastAPI | B5: =+Requisitos!C2 -> 1 | C5: 1 | D5: 0.25 | E5: Victor | F5: Completado
A6: Creación de fichero de dependencias del proyecto y subida al repositorio de github | B6: =+Requisitos!C2 -> 1 | C6: 0.17 | D6: 0.083 | E6: Victor | F6: Completado
A7: Creación de fichero de servidor web con FastAPI y tests iniciales de comprobación | B7: =+Requisitos!C2 -> 1 | C7: 1 | D7: 0.5 | E7: Victor | F7: Completado
A8: Estudio de la documentación de FastAPI | B8: =+Requisitos!C2 -> 1 | C8: 2 | D8: 1 | E8: Pablo | F8: Completado
A9: Estudio de la documentación de FastAPI | B9: =+Requisitos!C2 -> 1 | C9: 2 | D9: 1 | E9: Alfredo | F9: Completado
A10: Estudio de la documentación de FastAPI | B10: =+Requisitos!C2 -> 1 | C10: 1 | D10: 1 | E10: Javier | F10: Completado
A11: Creación y edición de fichero HTML para endpoint "/" | B11: =+Requisitos!C4 -> 3 | C11: 0.5 | D11: 0.25 | E11: Victor | F11: Completado
A12: Creación de tests para landing page | B12: =+Requisitos!C4 -> 3 | C12: 0.17 | D12: 0.083 | E12: Victor | F12: Completado
A13: Modificación del HTML para mostrar más información acerca de la utilidad de la página | B13: =+Requisitos!C4 -> 3 | C13: 0.083 | D13: 0.12 | E13: Juan | F13: Completado
A14: Creación de más tests para funcionalidad de landing page | B14: =+Requisitos!C4 -> 3 | C14: 0.17 | D14: 0.25 | E14: Victor | F14: Completado
A15: Edición de fichero servidor para devolver HTMLs a la página web | B15: =+Requisitos!C4 -> 3 | C15: 0.083 | D15: 0.17 | E15: Victor | F15: Completado
A16: Creación y edición de fichero HTML para endpoint "/menu-semanal" | B16: =+Requisitos!C7 -> 6 | C16: 0.25 | D16: 0.5 | E16: Alfredo | F16: Completado
A17: Creación de tests para endpoint de menú semanal | B17: =+Requisitos!C7 -> 6 | C17: 1 | D17: 2 | E17: Alfredo | F17: Completado
A18: Creación de nuevo endpoint para las recetas | B18: =+Requisitos!C5 -> 4 | C18: 2 | D18: 1 | E18: Pablo | F18: Completado
A19: Creación de tests para endpoint de las recetas | B19: =+Requisitos!C5 -> 4 | C19: 0.15 | D19: 0.25 | E19: Pablo | F19: Completado
A20: Creación de botón para crear cuenta en HTML | B20: =+Requisitos!C10 -> 9 | C20: 1 | D20: 0.5 | E20: Javier | F20: Completado
A21: Creación de diálogo con formulario para introducir datos y enviarlos al servidor | B21: =+Requisitos!C10 -> 9 | C21: 0.5 | D21: 0.5 | E21: Victor | F21: Completado
A22: Guardar información de la cuenta creada en el servidor | B22: =+Requisitos!C10 -> 9 | C22: 0.5 | D22: 0.75 | E22: Victor | F22: Completado
A23: Estudio de configuración de conda | B23: =+Requisitos!C2 -> 1 | C23: 0.5 | D23: 1 | E23: Javier | F23: Completado
A24: Estudio de configuración de conda | B24: =+Requisitos!C2 -> 1 | C24: 1 | D24: 1.5 | E24: Pablo | F24: Completado
A25: Mostrar mensaje en HTML tras la finalización de cuenta creada | B25: =+Requisitos!C10 -> 9 | C25: 0.25 | D25: 0.75 | E25: Javier | F25: Completado
A26: Refactoring del código | C26: 0.5 | D26: 0.15 | E26: Victor | F26: Completado
A27: Mostrar menú/formulario para la creación de la receta (HTML) | B27: =+Requisitos!C20 -> 19 | C27: 1 | D27: 0.5 | E27: Pedro | F27: Completado
A28: Mostrar botón para sacar el formulario de creación de las recetas de comida | B28: =+Requisitos!C20 -> 19 | C28: 0.15 | D28: 0.083 | E28: Pedro | F28: Completado
A29: Estudio de Javascript | B29: =+Requisitos!C5 -> 4 | C29: 0.5 | D29: 1 | E29: Pablo | F29: Completado
A30: Creación de nuevo endpoint para recibir la información de la creación de nueva receta | B30: =+Requisitos!C20 -> 19 | C30: 1 | D30: 0.15 | E30: Victor | F30: Completado
A31: Creación de código Javascript para mandar formulario al servidor | B31: =+Requisitos!C20 -> 19 | C31: 0.5 | D31: 1 | E31: Victor | F31: Completado
A32: Creación de código Javascript para ocultar el diálogo del formulario y mostrar mensaje de éxito de creación de una receta de comida | B32: =+Requisitos!C20 -> 19 | C32: 0.25 | D32: 1 | E32: Victor | F32: Completado
A33: Creación de un botón HTML de inicio de sesión | B33: =+Requisitos!C11 -> 10 | C33: 0.25 | D33: 0.5 | E33: Juan | F33: Completado
A34: Reutilizar codigo de crear cuenta para formulario de inicio de sesion | B34: =+Requisitos!C11 -> 10 | C34: 1 | D34: 1.5 | E34: Juan | F34: Completado
A35: Mostrar mensaje de éxito tras pulsar el boton al finalizar | B35: =+Requisitos!C11 -> 10 | C35: 2 | D35: 3 | E35: Juan | F35: Completado
A36: Modificar el formulario de crear receta para aceptar los nuevos campos | B36: =+Requisitos!C21 -> 20 | C36: 1 | D36: 2 | E36: Alfredo | F36: Completado
A37: Modificar el endpoint de crear receta para que reconozca los datos enviados | B37: =+Requisitos!C21 -> 20 | C37: 1.5 | D37: 2.5 | E37: Alfredo | F37: Completado
A38: Estudiar documentación necesaria | B38: =+Requisitos!C12 -> 11 | C38: 2 | D38: 1 | E38: Pedro | F38: Completado
A39: Crear un botón HTML de cerrar sesión | B39: =+Requisitos!C12 -> 11 | C39: 0.5 | D39: 0.5 | E39: Pedro | F39: Completado
A40: Reutilizar codigo del "Modal" para mostrar el dialogo de cerrar sesión | B40: =+Requisitos!C12 -> 11 | C40: 0.5 | D40: 0.5 | E40: Pedro | F40: Completado
...

Sheet Requisitos
A1: Requisito | B1: Criterio de validacion | C1: ID | D1: Priority | E1: Tiempo planning poker (horas) | F1: Riesgo | G1: Entrega | H1: Estado
A2: Se requiere de una página web que muestre el contenido de la idea del recetario de comidas | B2: 1. Al crear una nueva receta, si no se introduce un valor para el nombre, no debe dejar mandar el formulario y debe mostrar un aviso. 2. Al crear una nueva receta, si no se introduce un valor para el descripcion, no debe dejar mandar el formulario y debe mostrar un aviso. 3. Al crear una nueva receta, si no se introduce un valor para ingredientes, no debe dejar mandar el formulario y debe mostrar un aviso. 4. Al crear una nueva receta, si no se introduce un valor para los pasos a seguir, no debe dejar mandar el formulario y debe mostrar un aviso. 5. Al crear una nueva receta, si no se introduce un valor para la duración, no debe dejar mandar el formulario y debe mostrar un aviso. 6. Al crear una nueva receta, si no se introduce un valor para la foto, no debe dejar mandar el formulario y debe mostrar un aviso. 7. Si se introducen todos los campos obligatorios en el formulario, este se manda. 8. Cuando se mande el formulario correctamente, se debe mostrar un mensaje de éxito | C2: 1 | D2: I | E2: 5 | F2: Medio | G2: 45929 | H2: Completado
A3: Se requiere que la página web sea responsive (se adapte al tamaño de la pantalla del cliente). | B3: 1.Si no estás iniciado sesión, si clickas cualquier opción de la landing page(excepto inicio o el boton de recetario online), debe redirigirte a un formulario para iniciar sesión. 2. Si no se ha iniciado sesión debe aparecer la opción de iniciar sesión y crear cuenta, pero no la de cerrar sesión. 3. Debe aparecer un contenido que indique que se está utilizando la página web en modo invitado. | C3: 2 | D3: C | E3: 13 | F3: Alto | H3: Pendiente
A4: La página web debe contar con una página de bienvenida (landing page) que muestre información acerca de la utilidad de la misma y de sus distintos apartados. | B4: 1.Si un usuario invitado inicia sesión, al clickar cualquier botón o apartado, se le permitirá acceder al mismo. 2. En vez de aparecer los botones de iniciar sesión y crear cuenta, debe salir la opción de cerrar sesión en la landing page. 3. Debe aparecer un contenido que muestre un icono de ejemplo en la esquina superior derecha cuando un usuario esté registrado | C4: 3 | D4: I | E4: 3 | F4: Bajo | G4: 45929 | H4: Completado
A5: La página web debe contar con un apartado que muestre un menú de recetas del usuario | B5: 1. Un usuario con la sesión iniciada deberá tener la opción de cerrar sesión desde los distintos apartado de la página 2. Si se selecciona la opción de cerrar sesión desde cualquier apartado, se le redirigirá al usuario a la landing page como usuario invitado (sin permisos para entrar al resto de apartados). 3. Debe aparecer un contenido que indique que se está utilizando la página web en modo invitado. | C5: 4 | D5: N | E5: 3 | F5: Bajo | G5: 45929 | H5: Completado
A6: La página web debe contar con un apartado que muestre recetas publicadas por otros usuarios. | B6: 1. Siendo un usuario con inicio de sesión ya realizado, este debe poder acceder al apartado de recetas y observar las tres diferentes opciones. 2. Si el usuario selecciona la opción de "Mis Recetas" se le redirigirá a una página donde se le muestran sus recetas. 3. Si el usuario selecciona la opción de "Recetas guardadas" se le redirigirá a una página donde se le muestren sus recetas guardadas. 4. Si el usuario selecciona la opción de "Crear Receta" se le mostrará un formulario directamente para introducir los campos correspondientes. | C6: 5 | D6: N | E6: 10 | F6: Medio | H6: Pendiente
A7: La página web debe contar con un apartado que muestre un menú para la creación de un menú semanal de comidas. | B7: 1. Un usuario con la sesión iniciada debe tener la opción de acceder al apartado "Mis recetas" desde el apartado "Recetas". 2. Un usuario, al acceder al apartado "Mis recetas", debe poder observar un titulo que indique que está en el apartado de "Mis recetas". 3.Si un usuario ya con la sesión iniciada accede al apartado de mis recetas, se le deben mostrar solamente sus recetas y no las de otros usuarios. 4. Debe aparecer la opción de crear nueva receta de comida en este apartado. 5. Si se crea una nueva receta desde este apartado, la página web automáticamente mostrará la nueva receta creada junto con el resto de recetas de comida mostradas. 6. Dentro de este apartado, se mostrarán todas las recetas propias del usuario mostrando el título, descripción, foto, duración. | C7: 6 | D7: I | E7: 8 | F7: Medio | G7: 45929 | H7: Completado
A8: La página web contemplará un tipo de usuario denominado: usuario invitado. Este usuario no se habrá registrado ni iniciado sesión y solo tendrá acceso a la landing page. | B8: 1. Al crear una cuenta, si no se introduce un valor para el nombre de usuario, no debe dejar mandar el formulario y debe mostrar un mensaje de aviso. 2. Al crear una cuenta, si no se introduce un valor para el email, no debe dejar mandar el formulario y debe mostrar un mensaje de aviso. 3. Al crear una cuenta, si no se introduce un valor para la contraseña, no debe dejar mandar el formulario y debe mostrar un mensaje de aviso. 4. Si se introducen todos los campos, debe dejar mandar el formulario. 5. Se mostrará un mensaje de éxito cuando se mande correctamente el formulario. | C8: 7 | D8: N | E8: 6 | F8: Bajo | H8: Pendiente
A9: Se denegará el acceso a cualquier usuario invitado que intente acceder a otro apartado que no sea de la landing page. | B9: 1. Al iniciar sesión, si no se introduce un valor para el email, no debe dejar mandar el formulario y debe mostrar un mensaje de aviso. 2. Al iniciar sesión, si no se introduce un valor para la contraseña, no debe dejar mandar el formulario y debe mostrar un mensaje de aviso. 3. Si se introducen todos los campos, debe dejar mandar el formulario. 4. Se mostrará un mensaje de éxito cuando se mande correctamente el formulario. | C9: 8 | D9: N | E9: 5 | F9: Medio | H9: Pendiente
A10: La landing page debe contener la posibilidad de permitir a un usuario invitado crearse una cuenta. | B10: 1. Si se introduce en cualquier formulario una contraseña con menos de 8 caracteres, no debe dejar mandar el formulario y debe mostrar un mensaje de aviso. 2. Si se introduce en cualquier formulario una contraseña que no contiene mínimo una letra mayúscula, no debe dejar mandar el formulario y debe mostrar un mensaje de aviso. 3. Si se introduce en cualquier formulario una contraseña con mínimo una letra minúscula, no debe dejar mandar el formulario y debe mostrar un mensaje de aviso. 4. Si se introduce en cualquier formulario una contraseña con mínimo un número, no debe dejar mandar el formulario y debe mostrar un mensaje de aviso. | C10: 9 | D10: I | E10: 10 | F10: Alto | G10: 45929 | H10: Completado
A11: La landing page debe contener la posibilidad de permitir a un usuario invitado iniciar sesión con una cuenta. | B11: 1. Si se introduce en cualquier formulario un email con menos de 8 caracteres en la parte local, no debe dejar mandar el formulario y debe mostrar un mensaje de aviso. 2. Si se introduce en cualquier formulario un email con cualquier caracter que no sea una letra, número o punto, no debe dejar mandar el formulario y debe mostrar un mensaje de aviso. 3. Si se introduce en cualquier formulario un email sin arroba, no debe dejar mandar el formulario y debe mostrar un mensaje de aviso. 4. Si se introduce en cualquier formulario un email con más de un arroba, no debe dejar mandar el formulario y debe mostrar un mensaje de aviso. 5. Si se introduce en cualquier formulario un email con un dominio fuera de los especificados en el requisito, no debe dejar mandar el formulario y debe mostrar un mensaje de aviso. | C11: 10 | D11: I | E11: 13 | F11: Alto | G11: 45936 | H11: Completado
A12: La página web deberá contener, desde cualquier apartado, la posibilidad de cerrar sesión a un usuario registrado. | C12: 11 | D12: N | E12: 4 | F12: Medio | G12: 45936 | H12: Completado
A13: La página web deberá contener, desde cualquier apartado, la posibilidad de editar cuenta a un usuario registrado. | C13: 12 | D13: C | E13: 6 | F13: Medio | H13: Pendiente
A14: La página web contemplará un tipo de usuario denominado: usuario registrado. Este usuario habrá iniciado sesión con una cuenta y tendrá acceso a todos los apartados. | C14: 13 | D14: N | E14: 13 | F14: Alto | H14: Pendiente
A15: La página web no debe guardar información sensible de la cuenta del usuario (ej: contraseña) en claro. Debe estar protegida por algún mecanismo de seguridad ante posibles fallos de seguridad. (Ej: cifrar contraseñas) . | C15: 14 | D15: C | E15: 5 | F15: Medio
A16: La página web debe permitir cambiar el idioma del texto. | C16: 15 | D16: C | E16: 2 | F16: Bajo | H16: Pendiente
A17: Se requiere que el sistema mantenga información persistente. | C17: 16 | D17: N | E17: 10 | F17: Alto | H17: Pendiente
A18: Se requiere que el sistema tenga la posibilidad de escalar. | C18: 17 | D18: C | E18: 15 | F18: Alto | H18: Pendiente
A19: Se requiere que cada cuenta de usuario sea única, es decir, que cada cuenta sea solo de un usuario. | C19: 18 | D19: N | E19: 0.5 | F19: Bajo | H19: Pendiente
A20: Dentro del apartado del menú de las recetas del usuario, se debe poder crear una receta nueva. | C20: 19 | D20: I | E20: 13 | F20: Medio | G20: 45929 | H20: Completado
A21: A la hora de crear una nueva receta se debe poder introducir manualmente los pasos a seguir, ingredientes, alérgenos, nombre, foto, tipo de comida (entendido como país de origen) turno de comida (si es de comida, desayuno, cena...), dificultad de la receta y duración. | C21: 20 | D21: N | E21: 5 | F21: Medio | G21: 45936 | H21: Completado
A22: Dentro del apartado de las recetas se debe poder editar o modificar las recetas propias del usuario, cambiando los campos de la información de la receta. | C22: 21 | D22: C | E22: 3 | F22: Medio | H22: Pendiente
A23: Dentro del apartado de las recetas un usuario no deberá poder editar una receta de la que no es propietario. | C23: 22 | D23: C | E23: 1 | F23: Bajo | H23: Pendiente
A24: Dentro del apartado de las recetas se debe poder eliminar las recetas propias del usuario. | C24: 23 | D24: C | E24: 1 | F24: Bajo | H24: Pendiente
A25: Dentro del apartado de recetas se podrán visualizar todas las recetas creadas por el usuario. | C25: 24 | D25: N | E25: 9 | F25: Alto | H25: Pendiente
A26: Dentro del apartado de recetas se podrán visualizar todas las recetas guardadas por el usuario (no son de su propiedad). | C26: 25 | D26: N | E26: 10 | F26: Medio | H26: Pendiente
A27: Dentro del apartado de las recetas creadas, el usuario puede decidir si publicarlas (ser visibles por el resto de los usuarios). | C27: 26 | D27: C | E27: 3 | F27: Bajo | H27: Pendiente
A28: Independientemente del apartado en el que se encuentre un usuario, al acceder a una receta que no sea propia, se le permitirá poner una valoración y/o un comentario. | C28: 27 | D28: C | E28: 20 | F28: Alto | H28: Pendiente
A29: Cada usuario registrado de la página web tendrá una valoración general en función de las valoraciones de sus recetas, que se podrá visualizar en el perfil. | C29: 28 | D29: C | E29: 15 | F29: Alto | H29: Pendiente
A30: Dentro del apartado de las recetas publicadas por usuarios, se podrá filtrar en función de en función de: ingredientes, alérgenos, nombre, foto, tipo de comida (entendido como país de origen) turno de comida (si es de comida, desayuno, cena...), dificultad de la receta y duración. | C30: 29 | D30: C | E30: 10 | F30: Medio | H30: Pendiente
A31: Dentro del apartado de las recetas publicadas por otros usuarios, si un usuario accede a una receta se le permitirá guardar la receta. | C31: 30 | D31: I | E31: 15 | F31: Medio | H31: Pendiente
A32: Dentro del apartado del menú semanal se debe poder generar un menú semanal automáticamente en función de las recetas propias y guardadas. | C32: 31 | D32: N | E32: 25 | F32: Alto | H32: Pendiente
A33: Dentro del apartado del menú semanal se debe poder editar el menú semanal. | C33: 32 | D33: C | E33: 12 | F33: Alto | H33: Pendiente
... A37: El elemento único dentro de una cuenta es el email, es decir, no pueden existir dos cuentas distintas con el mismo email. | C37: 36 | D37: C | E37: 4 | F37: Bajo | H37: Completado
A38: Al crear una receta, los siguientes campos son obligatorios: nombre, descripcion, ingredientes, pasos a seguir, duracion, foto | B38: 1. Al crear una nueva receta, si no se introduce un valor para el nombre, no debe dejar mandar el formulario y debe mostrar un aviso. 2. Al crear una nueva receta, si no se introduce un valor para el descripcion, no debe dejar mandar el formulario y debe mostrar un aviso. 3. Al crear una nueva receta, si no se introduce un valor para ingredientes, no debe dejar mandar el formulario y debe mostrar un aviso. 4. Al crear una nueva receta, si no se introduce un valor para los pasos a seguir, no debe dejar mandar el formulario y debe mostrar un aviso. 5. Al crear una nueva receta, si no se introduce un valor para la duración, no debe dejar mandar el formulario y debe mostrar un aviso. 6. Al crear una nueva receta, si no se introduce un valor para la foto, no debe dejar mandar el formulario y debe mostrar un aviso. 7. Si se introducen todos los campos obligatorios en el formulario, este se manda. 8. Cuando se mande el formulario correctamente, se debe mostrar un mensaje de éxito | C38: 37 | D38: I | E38: 3 | F38: Medio | G38: 45944 | H38: Completado
A39: Siempre que un usuario esté creando una receta nueva, debe tener la opción de guardar o no la nueva receta. | C39: 38 | D39: I | E39: 8 | F39: Alto | H39: Pendiente
A41: Un usuario invitado no puede acceder a ningún apartado que no sea la landing page | B41: 1.Si no estás iniciado sesión, si clickas cualquier opción de la landing page(excepto inicio o el boton de recetario online), debe redirigirte a un formulario para iniciar sesión. 2. Si no se ha iniciado sesión debe aparecer la opción de iniciar sesión y crear cuenta, pero no la de cerrar sesión. 3. Debe aparecer un contenido que indique que se está utilizando la página web en modo invitado. | C41: 39 | D41: I | E41: 12 | F41: Alto | G41: 45944 | H41: Completado
A42: Un usuario registrado(ya ha iniciado sesión) tendrá acceso a cualquier apartado de la página web. | B42: 1.Si un usuario invitado inicia sesión, al clickar cualquier botón o apartado, se le permitirá acceder al mismo. 2. En vez de aparecer los botones de iniciar sesión y crear cuenta, debe salir la opción de cerrar sesión en la landing page. 3. Debe aparecer un contenido que muestre un icono de ejemplo en la esquina superior derecha cuando un usuario esté registrado | C42: 40 | D42: I | E42: 30 | F42: Medio | G42: 45944 | H42: Completado
A43: Una vez el usuario cierre sesión, se le debe redirigir a la landing page de usuario invitado | B43: 1. Un usuario con la sesión iniciada deberá tener la opción de cerrar sesión desde los distintos apartado de la página 2. Si se selecciona la opción de cerrar sesión desde cualquier apartado, se le redirigirá al usuario a la landing page como usuario invitado (sin permisos para entrar al resto de apartados). 3. Debe aparecer un contenido que indique que se está utilizando la página web en modo invitado. | C43: 41 | D43: I | E43: 4 | F43: Medio | G43: 45944 | H43: Completado
A44: El apartado de recetas debe contener tres apartados diferentes: "Mis recetas", "Recetas Guardadas" y "Crear Receta". | B44: 1. Siendo un usuario con inicio de sesión ya realizado, este debe poder acceder al apartado de recetas y observar las tres diferentes opciones. 2. Si el usuario selecciona la opción de "Mis Recetas" se le redirigirá a una página donde se le muestran sus recetas. 3. Si el usuario selecciona la opción de "Recetas guardadas" se le redirigirá a una página donde se le muestren sus recetas guardadas. 4. Si el usuario selecciona la opción de "Crear Receta" se le mostrará un formulario directamente para introducir los campos correspondientes. | C44: 42 | D44: I | E44: 20 | F44: Medio | G44: 45944 | H44: Completado
...
